<?xml version="1.0" encoding="utf-8"?>
<robot name="Q1">
<!-- pelvis -->
  <link name="pelvis_link">
    <inertial>
      <origin xyz="-0.0487762750387871 -9.11331157705215E-19 -0.0596500367715889" rpy="0 0 0" />
      <mass value="4.85375453300402" />
      <inertia ixx="0.0338660906248352" ixy="7.84543415810989E-18" ixz="2.23402732944577E-05" iyy="0.0157992435830402" iyz="-5.16210957298333E-18" izz="0.0392683813104757" />
    </inertial>
    <visual>
      <origin xyz="0 0 0" rpy="0 0 0" />
      <geometry>
        <mesh filename="package://Q1/meshes/pelvis_link.STL" />
      </geometry>
      <material name="">
        <color rgba="0.792156862745098 0.819607843137255 0.933333333333333 1" />
      </material>
    </visual>
    <collision>
      <origin xyz="-0.1 0 -0.05" rpy="0 0 0" />
      <geometry>
        <box size="0.08 0.35 0.1"/>
        <!-- <mesh filename="package://Q1/meshes/pelvis_link.STL" /> -->
      </geometry>
    </collision>
  </link>

<!-- Left leg -->
  <link name="L_hip_roll_link">
    <inertial>
      <origin xyz="-0.0141876569739443 -3.74949976629513E-06 0.00614400116829972" rpy="0 0 0" />
      <mass value="1.25324354201009" />
      <inertia ixx="0.00131833796382136" ixy="-1.82413613026061E-07" ixz="-3.76732121233135E-05" iyy="0.0017092864744351" iyz="-1.36088720808342E-07" izz="0.00213328110485283" />
    </inertial>
    <visual>
      <origin xyz="0 0 0" rpy="0 0 0" />
      <geometry>
        <mesh filename="package://Q1/meshes/L_hip_roll_link.STL" />
      </geometry>
      <material name="">
        <color rgba="0.792156862745098 0.819607843137255 0.933333333333333 1" />
      </material>
    </visual>
    <collision>
      <origin xyz="0 0 0" rpy="0 0 0" />
      <geometry>
        <!-- <mesh filename="package://Q1/meshes/L_hip_roll_link.STL" /> -->
        <cylinder radius="0.025" length="0.017"/>
      </geometry>
    </collision>
  </link>
  <joint name="L_hip_roll_joint" type="revolute"><!-- EC-A8112-P1-18 -->
    <origin xyz="0 0.115 -0.05874" rpy="0 0 0" />
    <parent link="pelvis_link" />
    <child link="L_hip_roll_link" />
    <axis xyz="1 0 0" />
    <limit lower="-0.12" upper="0.83" effort="90" velocity="16.441001554" />
  </joint>
  <link name="L_hip_yaw_link">
    <inertial>
      <origin xyz="-6.22829924863006E-10 -3.97470999169425E-09 -0.127754873862154" rpy="0 0 0" />
      <mass value="3.64631909766459" />
      <inertia ixx="0.0111351389929927" ixy="3.30651426492064E-09" ixz="9.12301100309305E-10" iyy="0.0139968062197672" iyz="1.82839173063689E-09" izz="0.0074705457114106" />
    </inertial>
    <visual>
      <origin xyz="0 0 0" rpy="0 0 0" />
      <geometry>
        <mesh filename="package://Q1/meshes/L_hip_yaw_link.STL" />
      </geometry>
      <material name="">
        <color rgba="0.792156862745098 0.819607843137255 0.933333333333333 1" />
      </material>
    </visual>
    <collision>
      <origin xyz="-2.7849E-05 -0.0008477 -0.11745" rpy="1.570796327 0 0" />
      <geometry>
        <!-- <mesh filename="package://Q1/meshes/L_hip_yaw_link.STL" /> -->
        <cylinder radius="0.025" length="0.04"/>
      </geometry>
    </collision>
  </link>
  <joint name="L_hip_yaw_joint" type="revolute"><!-- EC-6408-P2-25 -->
    <origin xyz="0 0 0" rpy="0 0 0" />
    <parent link="L_hip_roll_link" />
    <child link="L_hip_yaw_link" />
    <axis xyz="0 0 1" />
    <limit lower="-0.89" upper="0.89" effort="60" velocity="15.603243513" />
  </joint>
  <link name="L_hip_pitch_link">
    <inertial>
      <origin xyz="0.0118734795001622 -1.3689291630814E-08 -0.135284360088896" rpy="0 0 0" />
      <mass value="2.04935184270293" />
      <inertia ixx="0.0322378233994432" ixy="9.83274049113261E-10" ixz="0.000317233508166188" iyy="0.0312492836829024" iyz="2.96866335989203E-09" izz="0.00859313858129664" />
    </inertial>
    <visual>
      <origin xyz="0 0 0" rpy="0 0 0" />
      <geometry>
        <mesh filename="package://Q1/meshes/L_hip_pitch_link.STL" />
      </geometry>
      <material name="">
        <color rgba="0.792156862745098 0.819607843137255 0.933333333333333 1" />
      </material>
    </visual>
    <collision>
      <origin xyz="0 0 -0.12" rpy="0 0 0" />
      <geometry>
        <cylinder radius="0.025" length="0.09"/>
      </geometry>
    </collision>
  </link>
  <joint name="L_hip_pitch_joint" type="revolute"><!-- EC-A10020-P2-24 -->
    <origin xyz="0 0 -0.14" rpy="0 0 0" />
    <parent link="L_hip_yaw_link" />
    <child link="L_hip_pitch_link" />
    <axis xyz="0 1 0" />
    <limit lower="-0.89" upper="1.64" effort="330" velocity="12.88052988" />
  </joint>
  <link name="L_knee_link">
    <inertial>
      <origin xyz="0.00610185508162121 -1.09286336369419E-08 -0.130319266126611" rpy="0 0 0" />
      <mass value="5.84550624070991" />
      <inertia ixx="0.103290256491282" ixy="-4.36471539759122E-09" ixz="0.00248994631602866" iyy="0.106156568969131" iyz="-6.56129372231401E-10" izz="0.00906089499816433" />
    </inertial>
    <visual>
      <origin xyz="0 0 0" rpy="0 0 0" />
      <geometry>
        <mesh filename="package://Q1/meshes/L_knee_link.STL" />
      </geometry>
      <material name="">
        <color rgba="0.792156862745098 0.819607843137255 0.933333333333333 1" />
      </material>
    </visual>
    <collision>
      <origin xyz="0 0 -0.19" rpy="0 0 0" />
      <geometry>
        <cylinder radius="0.025" length="0.1"/>
      </geometry>
    </collision>
    <collision>
      <origin xyz="0 0 -0.35" rpy="0 0 0" />
      <geometry>
        <cylinder radius="0.025" length="0.1"/>
      </geometry>
    </collision>
    <collision>
      <origin xyz="0 0 0.0" rpy="1.570796327 0 0" />
      <geometry>
        <cylinder radius="0.025" length="0.1"/>
      </geometry>
    </collision>
  </link>
  <joint name="L_knee_joint" type="revolute"><!-- EC-A10020-P2-24 -->
    <origin xyz="0 0 -0.285" rpy="0 0 0" />
    <parent link="L_hip_pitch_link" />
    <child link="L_knee_link" />
    <axis xyz="0 1 0" />
    <limit lower="-0.1" upper="2.35" effort="330" velocity="12.88052988" />
  </joint>
  <link name="L_ankle_pitch_link">
    <inertial>
      <origin xyz="1.50453614986374E-19 0 0" rpy="0 0 0" />
      <mass value="0.00495302360887897" />
      <inertia ixx="7.89862404763441E-07" ixy="-5.96160245654892E-25" ixz="1.82938354400023E-24" iyy="1.2798828296822E-07" iyz="-2.82115422426287E-24" izz="8.38035368942849E-07" />
    </inertial>
    <visual>
      <origin xyz="0 0 0" rpy="0 0 0" />
      <geometry>
        <mesh filename="package://Q1/meshes/L_ankle_pitch_link.STL" />
      </geometry>
      <material name="">
        <color rgba="0.792156862745098 0.819607843137255 0.933333333333333 1" />
      </material>
    </visual>
    <collision>
      <origin xyz="0 0 0" rpy="0 0 0" />
      <geometry>
        <cylinder radius="0.001" length="0.001"/>
        <!-- <mesh filename="package://Q1/meshes/L_ankle_pitch_link.STL" /> -->
      </geometry>
    </collision>
  </link>
  <joint name="L_ankle_pitch_joint" type="revolute"><!-- EC-A4310-P2-36 -->
    <origin xyz="0 0 -0.451" rpy="0 0 0" />
    <parent link="L_knee_link" />
    <child link="L_ankle_pitch_link" />
    <axis xyz="0 1 0" />
    <limit lower="-0.43" upper="0.43" effort="36" velocity="9.320058206" />
  </joint>
  <link name="L_ankle_roll_link">
    <inertial>
      <origin xyz="0.034303989878725 0.230000022143615 -0.0341212606712048" rpy="0 0 0" />
      <mass value="0.700527444039911" />
      <inertia ixx="0.000476672716613184" ixy="-4.18118760679968E-09" ixz="0.00010510646806602" iyy="0.0032483279880811" iyz="6.20431199522967E-10" izz="0.00355171740661827" />
    </inertial>
    <visual>
      <origin xyz="0 0 0" rpy="0 0 0" />
      <geometry>
        <mesh filename="package://Q1/meshes/L_ankle_roll_link.STL" />
      </geometry>
      <material name="">
        <color rgba="0.792156862745098 0.819607843137255 0.933333333333333 1" />
      </material>
    </visual>
    <collision>
      <origin xyz="-0.068 0.032 -0.047" rpy="0 0 0"/>
      <geometry>
        <sphere radius="0.005"/>
      </geometry>
    </collision>
    <collision>
      <origin xyz="-0.068 -0.032 -0.047" rpy="0 0 0"/>
      <geometry>
        <sphere radius="0.005"/>
      </geometry>
    </collision>
    <collision>
      <origin xyz="-0.076 0 -0.047" rpy="0 0 0"/>
      <geometry>
        <sphere radius="0.005"/>
      </geometry>
    </collision>

    <collision>
      <origin xyz="0.148 0.032 -0.047" rpy="0 0 0"/>
      <geometry>
        <sphere radius="0.005"/>
      </geometry>
    </collision>
    <collision>
      <origin xyz="0.148 -0.032 -0.047" rpy="0 0 0"/>
      <geometry>
        <sphere radius="0.005"/>
      </geometry>
    </collision>
    <collision>
      <origin xyz="0.166 0 -0.047" rpy="0 0 0"/>
      <geometry>
        <sphere radius="0.005"/>
      </geometry>
    </collision>
  </link>
  <joint name="L_ankle_roll_joint" type="revolute"><!-- EC-A4310-P2-36 -->
    <origin xyz="0 0 0" rpy="0 0 0" />
    <parent link="L_ankle_pitch_link" />
    <child link="L_ankle_roll_link" />
    <axis xyz="1 0 0" />
    <limit lower="-0.43" upper="0.43" effort="36" velocity="9.320058206" />
  </joint>
<!-- Right leg -->
  <link name="R_hip_roll_link">
    <inertial>
      <origin xyz="-0.0141876569033487 3.75283373696411E-06 0.0061440013588332" rpy="0 0 0" />
      <mass value="1.25324353787124" />
      <inertia ixx="0.00131833795268296" ixy="1.82518219698434E-07" ixz="-3.76732072834159E-05" iyy="0.00170928646062036" iyz="1.36114793133514E-07" izz="0.00213328110797307" />
    </inertial>
    <visual>
      <origin xyz="0 0 0" rpy="0 0 0" />
      <geometry>
        <mesh filename="package://Q1/meshes/R_hip_roll_link.STL" />
      </geometry>
      <material name="">
        <color rgba="0.792156862745098 0.819607843137255 0.933333333333333 1" />
      </material>
    </visual>
    <collision>
      <origin xyz="0 0 0" rpy="0 0 0" />
      <geometry>
        <cylinder radius="0.025" length="0.017"/>
      </geometry>
    </collision>
  </link>
  <joint name="R_hip_roll_joint" type="revolute"><!-- EC-A8112-P1-18 -->
    <origin xyz="0 -0.115 -0.05874" rpy="0 0 0" />
    <parent link="pelvis_link" />
    <child link="R_hip_roll_link" />
    <axis xyz="1 0 0" />
    <limit lower="-0.83" upper="0.12" effort="90" velocity="16.441001554" />
  </joint>
  <link name="R_hip_yaw_link">
    <inertial>
      <origin xyz="1.61102011964652E-08 -1.27349166212376E-08 0.0122460458390036" rpy="0 0 0" />
      <mass value="3.64637969927244" />
      <inertia ixx="0.0111351662541288" ixy="3.37078960713146E-10" ixz="1.07331570079452E-10" iyy="0.0139968135041087" iyz="6.71529011063379E-10" izz="0.00747054788767058" />
    </inertial>
    <visual>
      <origin xyz="0 0 0" rpy="0 0 0" />
      <geometry>
        <mesh filename="package://Q1/meshes/R_hip_yaw_link.STL" />
      </geometry>
      <material name="">
        <color rgba="0.792156862745098 0.819607843137255 0.933333333333333 1" />
      </material>
    </visual>
    <collision>
      <origin xyz="-2.7849E-05 -0.0008477 -0.11745" rpy="1.570796327 0 0" />
      <geometry>
        <cylinder radius="0.025" length="0.04"/>
      </geometry>
    </collision>
  </link>
  <joint name="R_hip_yaw_joint" type="revolute"><!-- EC-6408-P2-25 -->
    <origin xyz="0 0 0" rpy="0 0 0" />
    <parent link="R_hip_roll_link" />
    <child link="R_hip_yaw_link" />
    <axis xyz="0 0 1" />
    <limit lower="-0.89" upper="0.89" effort="60" velocity="15.603243513" />
  </joint>
  <link name="R_hip_pitch_link">
    <inertial>
      <origin xyz="0.0118734977086639 -1.83007622944764E-08 -0.135284411296981" rpy="0 0 0" />
      <mass value="2.04935276321242" />
      <inertia ixx="0.0322378311563258" ixy="1.35839973256299E-09" ixz="0.000317238468510283" iyy="0.0312492917592858" iyz="1.67654419256679E-09" izz="0.00859314008536883" />
    </inertial>
    <visual>
      <origin xyz="0 0 0" rpy="0 0 0" />
      <geometry>
        <mesh filename="package://Q1/meshes/R_hip_pitch_link.STL" />
      </geometry>
      <material name="">
        <color rgba="0.792156862745098 0.819607843137255 0.933333333333333 1" />
      </material>
    </visual>
    <collision>
      <origin xyz="0 0 -0.12" rpy="0 0 0" />
      <geometry>
        <cylinder radius="0.025" length="0.09"/>
      </geometry>
    </collision>
  </link>
  <joint name="R_hip_pitch_joint" type="revolute"><!-- EC-A10020-P2-24 -->
    <origin xyz="0 0 -0.14" rpy="0 0 0" />
    <parent link="R_hip_yaw_link" />
    <child link="R_hip_pitch_link" />
    <axis xyz="0 1 0" />
    <limit lower="-0.89" upper="1.64" effort="330" velocity="12.88052988" />
  </joint>
  <link name="R_knee_link">
    <inertial>
      <origin xyz="0.00610184588200067 1.33535954793818E-08 -0.130319458287636" rpy="0 0 0" />
      <mass value="5.84551012436571" />
      <inertia ixx="0.103290592555704" ixy="6.89481487869816E-09" ixz="0.00248993087536182" iyy="0.106156898640285" iyz="-5.29040667291339E-10" izz="0.00906088945666182" />
    </inertial>
    <visual>
      <origin xyz="0 0 0" rpy="0 0 0" />
      <geometry>
        <mesh filename="package://Q1/meshes/R_knee_link.STL" />
      </geometry>
      <material name="">
        <color rgba="0.792156862745098 0.819607843137255 0.933333333333333 1" />
      </material>
    </visual>
    <collision>
      <origin xyz="0 0 -0.19" rpy="0 0 0" />
      <geometry>
        <cylinder radius="0.025" length="0.1"/>
      </geometry>
    </collision>
    <collision>
      <origin xyz="0 0 -0.35" rpy="0 0 0" />
      <geometry>
        <cylinder radius="0.025" length="0.1"/>
      </geometry>
    </collision>
    <collision>
      <origin xyz="0 0 0.0" rpy="1.570796327 0 0" />
      <geometry>
        <cylinder radius="0.025" length="0.1"/>
      </geometry>
    </collision>
  </link>
  <joint name="R_knee_joint" type="revolute"><!-- EC-A10020-P2-24 -->
    <origin xyz="0 0 -0.285" rpy="0 0 0" />
    <parent link="R_hip_pitch_link" />
    <child link="R_knee_link" />
    <axis xyz="0 1 0" />
    <limit lower="-0.1" upper="2.35" effort="330" velocity="12.88052988" />
  </joint>
  <link name="R_ankle_pitch_link">
    <inertial>
      <origin xyz="1.50453614986362E-19 0 6.93889390390723E-18" rpy="0 0 0" />
      <mass value="0.00495302360887897" />
      <inertia ixx="7.89862404763441E-07" ixy="5.9616024565489E-25" ixz="1.82938354400023E-24" iyy="1.2798828296822E-07" iyz="4.01347471557266E-24" izz="8.38035368942849E-07" />
    </inertial>
    <visual>
      <origin xyz="0 0 0" rpy="0 0 0" />
      <geometry>
        <mesh filename="package://Q1/meshes/R_ankle_pitch_link.STL" />
      </geometry>
      <material name="">
        <color rgba="0.792156862745098 0.819607843137255 0.933333333333333 1" />
      </material>
    </visual>
    <collision>
      <origin xyz="0 0 0" rpy="0 0 0" />
      <geometry>
        <cylinder radius="0.001" length="0.001"/>
      </geometry>
    </collision>
  </link>
  <joint name="R_ankle_pitch_joint" type="revolute"><!-- EC-A4310-P2-36 -->
    <origin xyz="0 0 -0.451" rpy="0 0 0" />
    <parent link="R_knee_link" />
    <child link="R_ankle_pitch_link" />
    <axis xyz="0 1 0" />
    <limit lower="-0.43" upper="0.43" effort="36" velocity="9.320058206" />
  </joint>
  <link name="R_ankle_roll_link">
    <inertial>
      <origin xyz="0.0343039957456198 -6.08531093848619E-08 -0.0341212535071516" rpy="0 0 0" />
      <mass value="0.700527402465685" />
      <inertia ixx="0.00047667302007158" ixy="5.00557754337453E-09" ixz="0.000105106590647267" iyy="0.00324832850684086" iyz="-1.05514204888278E-10" izz="0.00355171730474966" />
    </inertial>
    <visual>
      <origin xyz="0 0 0" rpy="0 0 0" />
      <geometry>
        <mesh filename="package://Q1/meshes/R_ankle_roll_link.STL" />
      </geometry>
      <material name="">
        <color rgba="0.792156862745098 0.819607843137255 0.933333333333333 1" />
      </material>
    </visual>
    <collision>
      <origin xyz="-0.068 0.032 -0.047" rpy="0 0 0"/>
      <geometry>
        <sphere radius="0.005"/>
      </geometry>
    </collision>
    <collision>
      <origin xyz="-0.068 -0.032 -0.047" rpy="0 0 0"/>
      <geometry>
        <sphere radius="0.005"/>
      </geometry>
    </collision>
    <collision>
      <origin xyz="-0.076 0 -0.047" rpy="0 0 0"/>
      <geometry>
        <sphere radius="0.005"/>
      </geometry>
    </collision>

    <collision>
      <origin xyz="0.148 0.032 -0.047" rpy="0 0 0"/>
      <geometry>
        <sphere radius="0.005"/>
      </geometry>
    </collision>
    <collision>
      <origin xyz="0.148 -0.032 -0.047" rpy="0 0 0"/>
      <geometry>
        <sphere radius="0.005"/>
      </geometry>
    </collision>
    <collision>
      <origin xyz="0.166 0 -0.047" rpy="0 0 0"/>
      <geometry>
        <sphere radius="0.005"/>
      </geometry>
    </collision>
  </link>
  <joint name="R_ankle_roll_joint" type="revolute"><!-- EC-A4310-P2-36 -->
    <origin xyz="0 0 0" rpy="0 0 0" />
    <parent link="R_ankle_pitch_link" />
    <child link="R_ankle_roll_link" />
    <axis xyz="1 0 0" />
    <limit lower="-0.43" upper="0.43" effort="36" velocity="9.320058206" />
  </joint>
<!-- torso -->
  <link name="torso_link">
    <inertial>
      <origin xyz="0.00053674 -1.8946E-09 0.23476" rpy="0 0 0" />
      <mass value="15.889" />
      <inertia ixx="0.2817047" ixy="1E-07" ixz="-0.0020139" iyy="0.2912939" iyz="0" izz="0.1172766" />
    </inertial>
    <visual>
      <origin xyz="0 0 0" rpy="0 0 0" />
      <geometry>
        <mesh filename="package://Q1/meshes/torso_link.STL" />
      </geometry>
      <material name="">
        <color rgba="0.86667 0.86667 0.8902 1" />
      </material>
    </visual>
    <collision>
      <origin xyz="-0.01 0 0.25" rpy="0 0 0" />
      <geometry>
        <box size="0.25 0.16 0.37"/>
      </geometry>
    </collision>
  </link>
  <joint name="pelvis_joint" type="revolute"><!-- CRA-RI60-80 -->
    <origin xyz="0 0 0" rpy="0 0 0" />
    <parent link="pelvis_link" />
    <child link="torso_link" />
    <axis xyz="0 0 1" />
    <limit lower="-1.04" upper="1.04" effort="42" velocity="8.58701992" />
  </joint>
<!-- Left arm -->
  <link name="L_shoulder_pitch_link">
    <inertial>
      <origin xyz="-0.00495795720364162 -0.00418267530064331 -3.95027721644681E-09" rpy="0 0 0" />
      <mass value="1.50011760905892" />
      <inertia ixx="0.00187402297134908" ixy="3.30316624760559E-05" ixz="-1.5724566950039E-08" iyy="0.00150513929190676" iyz="-3.20629087228975E-09" izz="0.00158895865973097" />
    </inertial>
    <visual>
      <origin xyz="0 0 0" rpy="-0.2618 0 0" />
      <geometry>
        <mesh filename="package://Q1/meshes/L_shoulder_pitch_link.STL" />
      </geometry>
      <material name="">
        <color rgba="0.792156862745098 0.819607843137255 0.933333333333333 1" />
      </material>
    </visual>
    <collision>
      <origin xyz="0 0 0" rpy="1.570796327 0 1.570796327"/>
      <geometry>
        <cylinder radius="0.025" length="0.03"/>
      </geometry>
    </collision>
  </link>
  <joint name="L_shoulder_pitch_joint" type="revolute"><!-- CRA-RI60-80 -->
    <origin xyz="0 0.2222 0.37445" rpy="0.2618 0 0" />
    <parent link="torso_link" />
    <child link="L_shoulder_pitch_link" />
    <axis xyz="0 1 0" />
    <limit lower="-1.48" upper="1.48" effort="42" velocity="8.58701992" />
  </joint>
  <link name="L_shoulder_roll_link">
    <inertial>
      <origin xyz="-0.00108082259395265 0.00237662147200235 -0.0619795684803297" rpy="0 0 0" />
      <mass value="0.548488874404492" />
      <inertia ixx="0.00143647468194247" ixy="-3.33011364832323E-06" ixz="5.86880632166666E-05" iyy="0.0017610979700737" iyz="-5.00767143394624E-05" izz="0.00117101030887955" />
    </inertial>
    <visual>
      <origin xyz="0 0 0" rpy="-0.2618 0 0" />
      <geometry>
        <mesh filename="package://Q1/meshes/L_shoulder_roll_link.STL" />
      </geometry>
      <material name="">
        <color rgba="0.898039215686275 0.917647058823529 0.929411764705882 1" />
      </material>
    </visual>
    <collision>
      <origin xyz="0 -0.001 -0.09" rpy="-0.2618 0 0" />
      <geometry>
        <cylinder radius="0.02" length="0.03"/>
      </geometry>
    </collision>
  </link>
  <joint name="L_shoulder_roll_joint" type="revolute"><!-- CRA-RI60-80 -->
    <origin xyz="0 0 0" rpy="0 0 0" />
    <parent link="L_shoulder_pitch_link" />
    <child link="L_shoulder_roll_link" />
    <axis xyz="1 0 0" />
    <limit lower="-0.12" upper="3.17" effort="42" velocity="8.58701992" />
  </joint>
  <link name="L_shoulder_yaw_link">
    <inertial>
      <origin xyz="-0.00328645079074991 -1.71252852801396E-06 0.0490996899087148" rpy="0 0 0" />
      <mass value="1.95077707562053" />
      <inertia ixx="0.00575990022758829" ixy="5.95802003784262E-09" ixz="-0.000315713576176404" iyy="0.00564262154536922" iyz="2.26801753669372E-07" izz="0.0017237170003833" />
    </inertial>
    <visual>
      <origin xyz="0 0 0" rpy="0 0 -1.570796327" />
      <geometry>
        <mesh filename="package://Q1/meshes/L_shoulder_yaw_link.STL" />
      </geometry>
      <material name="">
        <color rgba="0.792156862745098 0.819607843137255 0.933333333333333 1" />
      </material>
    </visual>
    <collision>
      <origin xyz="0 0 0.05" rpy="0 0 -1.570796327" />
      <geometry>
        <cylinder radius="0.02" length="0.06"/>
        <!-- <mesh filename="package://Q1/meshes/L_shoulder_yaw_link.STL" /> -->
      </geometry>
    </collision>
  </link>
  <joint name="L_shoulder_yaw_joint" type="revolute"><!-- CRA-RI50-70 -->
    <origin xyz="0 -0.043643 -0.25143" rpy="-0.2618 0 0" />
    <parent link="L_shoulder_roll_link" />
    <child link="L_shoulder_yaw_link" />
    <axis xyz="0 0 1" />
    <limit lower="-1.69" upper="1.69" effort="23" velocity="10.157816247" />
  </joint>
  <link name="L_elbow_link">
    <inertial>
      <origin xyz="-0.00389353915584163 0.00283878922194339 -0.0251500598389047" rpy="0 0 0" />
      <mass value="0.25017827413194" />
      <inertia ixx="0.000329525905517911" ixy="-2.84485568102828E-06" ixz="2.19534152936334E-05" iyy="0.000512035760158062" iyz="9.25015534028615E-06" izz="0.000456707595153785" />
    </inertial>
    <visual>
      <origin xyz="0 0 0" rpy="0 0 -1.570796327" />
      <geometry>
        <mesh filename="package://Q1/meshes/L_elbow_link.STL" />
      </geometry>
      <material name="">
        <color rgba="0.792156862745098 0.819607843137255 0.933333333333333 1" />
      </material>
    </visual>
    <collision>
      <origin xyz="0 0 -0.06" rpy="0 0 -1.570796327" />
      <geometry>
        <cylinder radius="0.02" length="0.03"/>
      </geometry>
    </collision>
  </link>
  <joint name="L_elbow_joint" type="revolute"><!-- CRA-RI50-70 -->
    <origin xyz="0 0 0" rpy="0 0 0" />
    <parent link="L_shoulder_yaw_link" />
    <child link="L_elbow_link" />
    <axis xyz="1 0 0" />
    <limit lower="-1.95" upper="0.87" effort="23" velocity="10.157816247" />
  </joint>
  <link name="L_forearm_yaw_link">
    <inertial>
      <origin xyz="-0.0019179869798028 -1.25212053114776E-07 0.106103751360934" rpy="0 0 0" />
      <mass value="1.04944082700571" />
      <inertia ixx="0.00202555517805004" ixy="5.62691576977426E-09" ixz="-5.87647945181155E-05" iyy="0.002122070152465" iyz="-2.2578268645124E-09" izz="0.000721248521569186" />
    </inertial>
    <visual>
      <origin xyz="0 0 0" rpy="0 0 0" />
      <geometry>
        <mesh filename="package://Q1/meshes/L_forearm_yaw_link.STL" />
      </geometry>
      <material name="">
        <color rgba="0.792156862745098 0.819607843137255 0.933333333333333 1" />
      </material>
    </visual>
    <collision>
      <origin xyz="0 0 0.082" rpy="0 0 0" />
      <geometry>
        <cylinder radius="0.025" length="0.03"/>
      </geometry>
    </collision>
  </link>
  <joint name="L_forearm_yaw_joint" type="revolute"><!-- CRA-RI40-52 -->
    <origin xyz="0 0 -0.231" rpy="0 0 0" />
    <parent link="L_elbow_link" />
    <child link="L_forearm_yaw_link" />
    <axis xyz="0 0 1" />
    <limit lower="-1.53" upper="1.53" effort="8.3" velocity="12.356931104" />
  </joint>
  <link name="L_wrist_roll_link">
    <inertial>
      <origin xyz="-1.48840306979354E-05 -0.00342715354445414 -3.20617582838523E-06" rpy="0 0 0" />
      <mass value="0.24994172305006" />
      <inertia ixx="8.33729148800578E-05" ixy="1.27519738119418E-08" ixz="-1.77957527391334E-08" iyy="6.15952338264229E-05" iyz="2.75090434504312E-09" izz="8.51129188951173E-05" />
    </inertial>
    <visual>
      <origin xyz="0 0 0" rpy="0 0 0" />
      <geometry>
        <mesh filename="package://Q1/meshes/L_wrist_roll_link.STL" />
      </geometry>
      <material name="">
        <color rgba="0.792156862745098 0.819607843137255 0.933333333333333 1" />
      </material>
    </visual>
    <collision>
      <origin xyz="0 0 0" rpy="0 1.570796327 0" />
      <geometry>
        <cylinder radius="0.015" length="0.01"/>
      </geometry>
    </collision>
  </link>
  <joint name="L_wrist_roll_joint" type="revolute"><!-- CRA-RI30-40 -->
    <origin xyz="0 0 0" rpy="0 0 0" />
    <parent link="L_forearm_yaw_link" />
    <child link="L_wrist_roll_link" />
    <axis xyz="1 0 0" />
    <limit lower="-2.3" upper="1.39" effort="3.3" velocity="12.356931104" />
  </joint>
  <link name="L_wrist_pitch_link">
    <inertial>
      <origin xyz="-5.63786121213732E-07 0.00812966481253333 -0.0518117287098212" rpy="0 0 0" />
      <mass value="0.150455726882542" />
      <inertia ixx="0.000108077289929613" ixy="1.47922508280712E-09" ixz="8.29368804505279E-11" iyy="9.0143623087068E-05" iyz="-3.56125612469369E-05" izz="5.85855867243114E-05" />
    </inertial>
    <visual>
      <origin xyz="0 0 0" rpy="0 0 0" />
      <geometry>
        <mesh filename="package://Q1/meshes/L_wrist_pitch_link.STL" />
      </geometry>
      <material name="">
        <color rgba="0.792156862745098 0.819607843137255 0.933333333333333 1" />
      </material>
    </visual>
    <collision>
      <origin xyz="0 0 -0.16" rpy="0 0 0" />
      <geometry>
        <box size="0.06 0.03 0.18"/>
      </geometry>
    </collision>
  </link>
  <joint name="L_wrist_pitch_joint" type="revolute"><!-- CRA-RI30-40 -->
    <origin xyz="0 0 0" rpy="0 0 0" />
    <parent link="L_wrist_roll_link" />
    <child link="L_wrist_pitch_link" />
    <axis xyz="0 1 0" />
    <limit lower="-1.78" upper="1.67" effort="3.3" velocity="12.356931104" />
  </joint>
<!-- Right arm -->
  <link name="R_shoulder_pitch_link">
    <inertial>
      <origin xyz="-0.00495802206787404 0.00418267582951914 -7.90797278771294E-08" rpy="0 0 0" />
      <mass value="1.50011657804918" />
      <inertia ixx="0.00187402350275849" ixy="-3.30332265847332E-05" ixz="-7.84415394758733E-09" iyy="0.00150513750159977" iyz="2.28818644237914E-09" izz="0.00158896079855835" />
    </inertial>
    <visual>
      <origin xyz="0 0 0" rpy="0.2618 0 0" />
      <geometry>
        <mesh filename="package://Q1/meshes/R_shoulder_pitch_link.STL" />
      </geometry>
      <material name="">
        <color rgba="0.792156862745098 0.819607843137255 0.933333333333333 1" />
      </material>
    </visual>
    <collision>
      <origin xyz="0 0 0" rpy="1.570796327 0 1.570796327"/>
      <geometry>
        <cylinder radius="0.025" length="0.03"/>
      </geometry>
    </collision>
  </link>
  <joint name="R_shoulder_pitch_joint" type="revolute"><!-- CRA-RI60-80 -->
    <origin xyz="0 -0.2222 0.37445" rpy="-0.2618 0 0" />
    <parent link="torso_link" />
    <child link="R_shoulder_pitch_link" />
    <axis xyz="0 1 0" />
    <limit lower="-1.48" upper="1.48" effort="42" velocity="8.58701992" />
  </joint>
  <link name="R_shoulder_roll_link">
    <inertial>
      <origin xyz="-0.00107995872117087 -0.00237583438433753 -0.0619790581829736" rpy="0 0 0" />
      <mass value="0.548544608828653" />
      <inertia ixx="0.00143631889336441" ixy="3.33596554308688E-06" ixz="5.87789958686636E-05" iyy="0.0017608995912366" iyz="5.00431693941603E-05" izz="0.00117101889882126" />
    </inertial>
    <visual>
      <origin xyz="0 0 0" rpy="0.2618 0 0" />
      <geometry>
        <mesh filename="package://Q1/meshes/R_shoulder_roll_link.STL" />
      </geometry>
      <material name="">
        <color rgba="0.792156862745098 0.819607843137255 0.933333333333333 1" />
      </material>
    </visual>
    <collision>
      <origin xyz="0 -0.001 -0.09" rpy="0.2618 0 0" />
      <geometry>
        <cylinder radius="0.02" length="0.03"/>
      </geometry>
    </collision>
  </link>
  <joint name="R_shoulder_roll_joint" type="revolute"><!-- CRA-RI60-80 -->
    <origin xyz="0 0 0" rpy="0 0 0" />
    <parent link="R_shoulder_pitch_link" />
    <child link="R_shoulder_roll_link" />
    <axis xyz="1 0 0" />
    <limit lower="-3.17" upper="0.12" effort="42" velocity="8.58701992" />
  </joint>
  <link name="R_shoulder_yaw_link">
    <inertial>
      <origin xyz="-0.00328637335590283 1.65717239394847E-06 0.0490998090017274" rpy="0 0 0" />
      <mass value="1.95078429643153" />
      <inertia ixx="0.00575988445324315" ixy="-3.22390758011475E-09" ixz="-0.000315703759879665" iyy="0.00564260187351902" iyz="-2.36710876067664E-07" izz="0.00172372509518998" />
    </inertial>
    <visual>
      <origin xyz="0 0 0" rpy="0 0 1.570796327" />
      <geometry>
        <mesh filename="package://Q1/meshes/R_shoulder_yaw_link.STL" />
      </geometry>
      <material name="">
        <color rgba="0.792156862745098 0.819607843137255 0.933333333333333 1" />
      </material>
    </visual>
    <collision>
      <origin xyz="0 0 0.05" rpy="0 0 -1.570796327" />
      <geometry>
        <cylinder radius="0.02" length="0.06"/>
      </geometry>
    </collision>
  </link>
  <joint name="R_shoulder_yaw_joint" type="revolute"><!-- CRA-RI50-70 -->
    <origin xyz="0 0.043643 -0.25143" rpy="0.2618 0 0" />
    <parent link="R_shoulder_roll_link" />
    <child link="R_shoulder_yaw_link" />
    <axis xyz="0 0 1" />
    <limit lower="-1.69" upper="1.69" effort="23" velocity="10.157816247" />
  </joint>
  <link name="R_elbow_link">
    <inertial>
      <origin xyz="-0.00389476701303175 -0.00283010868455533 -0.0251598722238591" rpy="0 0 0" />
      <mass value="0.250208538636712" />
      <inertia ixx="0.000329530169614741" ixy="2.76079103505772E-06" ixz="2.19552955696691E-05" iyy="0.000511998453902405" iyz="-9.24162905717076E-06" izz="0.000456679899635677" />
    </inertial>
    <visual>
      <origin xyz="0 0 0" rpy="0 0 1.570796327" />
      <geometry>
        <mesh filename="package://Q1/meshes/R_elbow_link.STL" />
      </geometry>
      <material name="">
        <color rgba="0.792156862745098 0.819607843137255 0.933333333333333 1" />
      </material>
    </visual>
    <collision>
      <origin xyz="0 0 -0.06" rpy="0 0 1.570796327" />
      <geometry>
        <cylinder radius="0.02" length="0.03"/>
      </geometry>
    </collision>
  </link>
  <joint name="R_elbow_joint" type="revolute"><!-- CRA-RI50-70 -->
    <origin xyz="0 0 0" rpy="0 0 0" />
    <parent link="R_shoulder_yaw_link" />
    <child link="R_elbow_link" />
    <axis xyz="1 0 0" />
    <limit lower="-0.87" upper="1.95" effort="23" velocity="10.157816247" />
  </joint>
  <link name="R_forearm_yaw_link">
    <inertial>
      <origin xyz="-0.00191812714203981 -1.93360864597647E-07 0.106102238720602" rpy="0 0 0" />
      <mass value="1.04948017603507" />
      <inertia ixx="0.00202555748383802" ixy="-6.12112083015588E-09" ixz="-5.87626468557779E-05" iyy="0.00212205767986656" iyz="-5.3482123752708E-09" izz="0.000721284921582001" />
    </inertial>
    <visual>
      <origin xyz="0 0 0" rpy="0 0 0" />
      <geometry>
        <mesh filename="package://Q1/meshes/R_forearm_yaw_link.STL" />
      </geometry>
      <material name="">
        <color rgba="0.792156862745098 0.819607843137255 0.933333333333333 1" />
      </material>
    </visual>
    <collision>
      <origin xyz="0 0 0.082" rpy="0 0 0" />
      <geometry>
        <cylinder radius="0.025" length="0.03"/>
      </geometry>
    </collision>
  </link>
  <joint name="R_forearm_yaw_joint" type="revolute"><!-- CRA-RI40-52 -->
    <origin xyz="0 0 -0.231" rpy="0 0 0" />
    <parent link="R_elbow_link" />
    <child link="R_forearm_yaw_link" />
    <axis xyz="0 0 1" />
    <limit lower="-1.53" upper="1.53" effort="8.3" velocity="12.356931104" />
  </joint>
  <link name="R_wrist_roll_link">
    <inertial>
      <origin xyz="-1.48739126234007E-05 0.0034271535183584 -3.18352502814978E-06" rpy="0 0 0" />
      <mass value="0.249941692839846" />
      <inertia ixx="8.33729109242616E-05" ixy="-1.27399507504747E-08" ixz="-1.78130623228303E-08" iyy="6.15952221189524E-05" iyz="-2.72314084654157E-09" izz="8.51129096598035E-05" />
    </inertial>
    <visual>
      <origin xyz="0 0 0" rpy="0 0 0" />
      <geometry>
        <mesh filename="package://Q1/meshes/R_wrist_roll_link.STL" />
      </geometry>
      <material name="">
        <color rgba="0.792156862745098 0.819607843137255 0.933333333333333 1" />
      </material>
    </visual>
    <collision>
      <origin xyz="0 0 0" rpy="0 1.570796327 0" />
      <geometry>
        <cylinder radius="0.015" length="0.01"/>
      </geometry>
    </collision>
  </link>
  <joint name="R_wrist_roll_joint" type="revolute"><!-- CRA-RI30-40 -->
    <origin xyz="0 0 0" rpy="0 0 0" />
    <parent link="R_forearm_yaw_link" />
    <child link="R_wrist_roll_link" />
    <axis xyz="1 0 0" />
    <limit lower="-1.39" upper="2.3" effort="3.3" velocity="12.356931104" />
  </joint>
  <link name="R_wrist_pitch_link">
    <inertial>
      <origin xyz="4.50781296785475E-07 -0.00812859839613109 -0.0518129718936489" rpy="0 0 0" />
      <mass value="0.150463482385983" />
      <inertia ixx="0.000108077969009104" ixy="9.06255747030998E-10" ixz="2.62193092852931E-11" iyy="9.01455762053942E-05" iyz="3.5610401266392E-05" izz="5.85887230654124E-05" />
    </inertial>
    <visual>
      <origin xyz="0 0 0" rpy="0 0 0" />
      <geometry>
        <mesh filename="package://Q1/meshes/R_wrist_pitch_link.STL" />
      </geometry>
      <material name="">
        <color rgba="0.792156862745098 0.819607843137255 0.933333333333333 1" />
      </material>
    </visual>
    <collision>
      <origin xyz="0 0 -0.16" rpy="0 0 0" />
      <geometry>
        <box size="0.06 0.03 0.18"/>
      </geometry>
    </collision>
  </link>
  <joint name="R_wrist_pitch_joint" type="revolute"><!-- CRA-RI30-40 -->
    <origin xyz="0 0 0" rpy="0 0 0" />
    <parent link="R_wrist_roll_link" />
    <child link="R_wrist_pitch_link" />
    <axis xyz="0 1 0" />
    <limit lower="-1.78" upper="1.67" effort="3.3" velocity="12.356931104" />
  </joint>
<!-- Head -->
  <link name="head_yaw_link">
    <inertial>
      <origin xyz="7.49133747551065E-05 1.69107871851368E-09 -0.0309122980529686" rpy="0 0 0" />
      <mass value="0.801875605020622" />
      <inertia ixx="0.000831181171188023" ixy="-3.13601566338686E-12" ixz="-5.64499744094677E-07" iyy="0.000326037079423328" iyz="2.52887610891004E-11" izz="0.00106957415110737" />
    </inertial>
    <visual>
      <origin xyz="0 0 0" rpy="0 0 0" />
      <geometry>
        <mesh filename="package://Q1/meshes/head_yaw_link.STL" />
      </geometry>
      <material name="">
        <color rgba="0.792156862745098 0.819607843137255 0.933333333333333 1" />
      </material>
    </visual>
    <collision>
      <origin xyz="0 0 0" rpy="0 0 0" />
      <geometry>
        <box size="0.01 0.01 0.01"/>
      </geometry>
    </collision>
  </link>
  <joint name="head_yaw_joint" type="revolute">
    <origin xyz="0.012 0 0.617" rpy="0 0 0" />
    <parent link="torso_link" />
    <child link="head_yaw_link" />
    <axis xyz="0 0 1" />
    <limit lower="-1.57" upper="1.57" effort="2.52" velocity="29.216811679" />
  </joint>
  <link name="head_pitch_link">
    <inertial>
      <origin xyz="0.038564 -0.00051032 -0.0049167" rpy="0 0 0" />
      <mass value="0.8024" />
      <inertia ixx="0.0052548" ixy="1.3293E-06" ixz="0.00042557" iyy="0.0059555" iyz="-6.1007E-06" izz="0.0059314" />
    </inertial>
    <visual>
      <origin xyz="0 0 0" rpy="0 0 0" />
      <geometry>
        <mesh filename="package://Q1/meshes/head_pitch_link.STL" />
      </geometry>
      <material name="">
        <color rgba="0.79216 0.81961 0.93333 1" />
      </material>
    </visual>
    <collision>
      <origin xyz="0 0 0" rpy="0 0 0" />
      <geometry>
        <box size="0.01 0.12 0.12"/>
      </geometry>
    </collision>
  </link>
  <joint name="head_pitch_joint" type="revolute">
    <origin xyz="0 0 0" rpy="0 0 0" />
    <parent link="head_yaw_link" />
    <child link="head_pitch_link" />
    <axis xyz="0 1 0" />
    <limit lower="-0.38" upper="0.33" effort="1.26" velocity="58.433623357" />
  </joint>
</robot>