<?xml version="1.0" encoding="utf-8"?>
<robot name="Q1">
  <mujoco>
    <compiler meshdir="../meshes" discardvisual="false" />
  </mujoco>
  <!-- [CAUTION] uncomment when convert to mujoco -->
  <!-- <link name="world"></link>
  <joint name="floating_base_joint" type="floating">
    <parent link="world" />
    <child link="pelvis_link" />
  </joint> -->

<!-- pelvis -->
  <link name="pelvis_link">
    <inertial>
      <origin xyz="-0.059494 -3E-05 -0.050247" rpy="0 0 0" />
      <mass value="4.85" />
      <inertia ixx="0.040224" ixy="-8.3E-06" ixz="-0.0023326" iyy="0.016754" iyz="2.11E-05" izz="0.045978" />
    </inertial>
    <visual>
      <origin xyz="0 0 0" rpy="0 0 0" />
      <geometry>
        <mesh filename="meshes/pelvis_link.STL" />
      </geometry>
      <material name="">
        <color rgba="0.79216 0.81961 0.93333 1" />
      </material>
    </visual>
    <collision>
      <origin xyz="-0.1 0 -0.05" rpy="0 0 0" />
      <geometry>
        <box size="0.08 0.35 0.1"/>
      </geometry>
    </collision>
  </link>
<!-- Left leg -->
  <link name="L_hip_roll_link">
    <inertial>
      <origin xyz="-0.017355 3.27E-05 0.0052023" rpy="0 0 0" />
      <mass value="1.25" />
      <inertia ixx="0.0013325" ixy="8E-07" ixz="-1.9E-06" iyy="0.0017211" iyz="-1.8E-06" izz="0.0022727" />
    </inertial>
    <visual>
      <origin xyz="0 0 0" rpy="0 0 0" />
      <geometry>
        <mesh filename="meshes/L_hip_roll_link.STL" />
      </geometry>
      <material name="">
        <color rgba="0.79216 0.81961 0.93333 1" />
      </material>
    </visual>
    <collision>
      <origin xyz="0 0 0" rpy="0 0 0" />
      <geometry>
        <!-- <mesh filename="meshes/L_hip_roll_link.STL" /> -->
        <cylinder radius="0.025" length="0.017"/>
      </geometry>
    </collision>
  </link>
  <joint name="L_hip_roll_joint" type="revolute"><!-- EC-A8112-P1-18 -->
    <origin xyz="-9.9986E-05 0.115 -0.059738" rpy="0 0 0" />
    <parent link="pelvis_link" />
    <child link="L_hip_roll_link" />
    <axis xyz="1 0 0" />
    <limit lower="-0.12" upper="0.83" effort="52" velocity="16.441001554" />
  </joint>
  <link name="L_hip_yaw_link">
    <inertial>
      <origin xyz="-0.0004909 -0.0025588 -0.12649" rpy="0 0 0" />
      <mass value="3.65" />
      <inertia ixx="0.012216" ixy="2.3E-06" ixz="0.0001238" iyy="0.014779" iyz="-9.21E-05" izz="0.0082115" />
    </inertial>
    <visual>
      <origin xyz="0 0 0" rpy="0 0 0" />
      <geometry>
        <mesh filename="meshes/L_hip_yaw_link.STL" />
      </geometry>
      <material name="">
        <color rgba="0.79216 0.81961 0.93333 1" />
      </material>
    </visual>
    <collision>
      <!-- <origin xyz="0 0 0" rpy="0 0 0" /> -->
      <origin xyz="-2.7849E-05 -0.0008477 -0.11745" rpy="1.570796327 0 0" />
      <geometry>
        <!-- <mesh filename="meshes/L_hip_yaw_link.STL" /> -->
        <cylinder radius="0.025" length="0.04"/>
      </geometry>
    </collision>
  </link>
  <joint name="L_hip_yaw_joint" type="revolute"><!-- EC-6408-P2-25 -->
    <origin xyz="0 0 0" rpy="0 0 0" />
    <parent link="L_hip_roll_link" />
    <child link="L_hip_yaw_link" />
    <axis xyz="0 0 1" />
    <limit lower="-0.89" upper="0.89" effort="40" velocity="15.603243513" />
  </joint>
  <link name="L_hip_pitch_link">
    <inertial>
      <origin xyz="0.0099171 0.0018793 -0.13808" rpy="0 0 0" />
      <mass value="2.05" />
      <inertia ixx="0.033566" ixy="-9.03E-05" ixz="0.0007018" iyy="0.032512" iyz="-0.0003565" izz="0.0091417" />
    </inertial>
    <visual>
      <origin xyz="0 0 0" rpy="0 0 0" />
      <geometry>
        <mesh filename="meshes/L_hip_pitch_link.STL" />
      </geometry>
      <material name="">
        <color rgba="0.79216 0.81961 0.93333 1" />
      </material>
    </visual>
    <collision>
      <origin xyz="0 0 -0.12" rpy="0 0 0" />
      <geometry>
        <cylinder radius="0.025" length="0.09"/>
      </geometry>
    </collision>
  </link>
  <joint name="L_hip_pitch_joint" type="revolute"><!-- EC-A10020-P2-24 -->
    <origin xyz="0 0 -0.14" rpy="0 0 0" />
    <parent link="L_hip_yaw_link" />
    <child link="L_hip_pitch_link" />
    <axis xyz="0 1 0" />
    <limit lower="-1.64" upper="0.89" effort="130" velocity="12.88052988" />
  </joint>
  <link name="L_knee_link">
    <inertial>
      <origin xyz="0.0045282 -0.0007966 -0.10136" rpy="0 0 0" />
      <mass value="5.85" />
      <inertia ixx="0.099815" ixy="-8.15E-05" ixz="0.0016236" iyy="0.10276" iyz="0.0007306" izz="0.010767" />
    </inertial>
    <visual>
      <origin xyz="0 0 0" rpy="0 0 0" />
      <geometry>
        <mesh filename="meshes/L_knee_link.STL" />
      </geometry>
      <material name="">
        <color rgba="0.79216 0.81961 0.93333 1" />
      </material>
    </visual>
    <collision>
      <origin xyz="0 0 -0.19" rpy="0 0 0" />
      <geometry>
        <cylinder radius="0.025" length="0.1"/>
      </geometry>
    </collision>
    <collision>
      <origin xyz="0 0 -0.35" rpy="0 0 0" />
      <geometry>
        <cylinder radius="0.025" length="0.1"/>
      </geometry>
    </collision>
    <collision>
      <origin xyz="0 0 0.0" rpy="1.570796327 0 0" />
      <geometry>
        <cylinder radius="0.025" length="0.1"/>
      </geometry>
    </collision>
  </link>
  <joint name="L_knee_joint" type="revolute"><!-- EC-A10020-P2-24 -->
    <origin xyz="0 0 -0.28496" rpy="0 0 0" />
    <parent link="L_hip_pitch_link" />
    <child link="L_knee_link" />
    <axis xyz="0 1 0" />
    <limit lower="-0.1" upper="2.35" effort="130" velocity="12.88052988" />
  </joint>
  <link name="L_ankle_pitch_link">
    <inertial>
      <origin xyz="0 5.24E-05 0.0029854" rpy="0 0 0" />
      <mass value="0.046" />
      <inertia ixx="3.9E-06" ixy="0" ixz="0" iyy="3.6E-06" iyz="0" izz="3.4E-06" />
    </inertial>
    <visual>
      <origin xyz="0 0 0" rpy="0 0 0" />
      <geometry>
        <mesh filename="meshes/L_ankle_pitch_link.STL" />
      </geometry>
      <material name="">
        <color rgba="0.79216 0.81961 0.93333 1" />
      </material>
    </visual>
    <collision>
      <origin xyz="0 0 0" rpy="0 0 0" />
      <geometry>
        <cylinder radius="0.001" length="0.001"/>
        <!-- <mesh filename="meshes/L_ankle_pitch_link.STL" /> -->
      </geometry>
    </collision>
  </link>
  <joint name="L_ankle_pitch_joint" type="revolute"><!-- EC-A4310-P2-36 -->
    <origin xyz="0 -1.39E-05 -0.45087" rpy="0 0 0" />
    <parent link="L_knee_link" />
    <child link="L_ankle_pitch_link" />
    <axis xyz="0 1 0" />
    <limit lower="-0.43" upper="0.43" effort="36" velocity="9.320058206" />
  </joint>
  <link name="L_ankle_roll_link">
    <inertial>
      <origin xyz="0.031136 -2.53E-05 -0.033992" rpy="0 0 0" />
      <mass value="0.7" />
      <inertia ixx="0.0004381" ixy="-3E-07" ixz="0.0002452" iyy="0.003321" iyz="2E-07" izz="0.0034737" />
    </inertial>
    <visual>
      <origin xyz="0 0 0" rpy="0 0 0" />
      <geometry>
        <mesh filename="meshes/L_ankle_roll_link.STL" />
      </geometry>
      <material name="">
        <color rgba="0.79216 0.81961 0.93333 1" />
      </material>
    </visual>
    <collision>
      <origin xyz="-0.063 0.027 -0.047" rpy="0 0 0"/>
      <geometry>
        <sphere radius="0.005"/>
      </geometry>
    </collision>
    <collision>
      <origin xyz="-0.063 -0.027 -0.047" rpy="0 0 0"/>
      <geometry>
        <sphere radius="0.005"/>
      </geometry>
    </collision>
    <collision>
      <origin xyz="-0.071 0 -0.047" rpy="0 0 0"/>
      <geometry>
        <sphere radius="0.005"/>
      </geometry>
    </collision>

    <collision>
      <origin xyz="0.143 0.027 -0.047" rpy="0 0 0"/>
      <geometry>
        <sphere radius="0.005"/>
      </geometry>
    </collision>
    <collision>
      <origin xyz="0.143 -0.027 -0.047" rpy="0 0 0"/>
      <geometry>
        <sphere radius="0.005"/>
      </geometry>
    </collision>
    <collision>
      <origin xyz="0.156 0 -0.047" rpy="0 0 0"/>
      <geometry>
        <sphere radius="0.005"/>
      </geometry>
    </collision>
  </link>
  <joint name="L_ankle_roll_joint" type="revolute"><!-- EC-A4310-P2-36 -->
    <origin xyz="0 0 0" rpy="0 0 0" />
    <parent link="L_ankle_pitch_link" />
    <child link="L_ankle_roll_link" />
    <axis xyz="1 0 0" />
    <limit lower="-0.43" upper="0.43" effort="36" velocity="9.320058206" />
  </joint>
<!-- Right leg -->
  <link name="R_hip_roll_link">
    <inertial>
      <origin xyz="-0.017467 -3.32E-05 0.0053508" rpy="0 0 0" />
      <mass value="1.25" />
      <inertia ixx="0.0013322" ixy="-8E-07" ixz="1E-06" iyy="0.0017254" iyz="1.8E-06" izz="0.0022772" />
    </inertial>
    <visual>
      <origin xyz="0 0 0" rpy="0 0 0" />
      <geometry>
        <mesh filename="meshes/R_hip_roll_link.STL" />
      </geometry>
      <material name="">
        <color rgba="0.79216 0.81961 0.93333 1" />
      </material>
    </visual>
    <collision>
      <origin xyz="0 0 0" rpy="0 0 0" />
      <geometry>
        <cylinder radius="0.025" length="0.017"/>
      </geometry>
    </collision>
  </link>
  <joint name="R_hip_roll_joint" type="revolute"><!-- EC-A8112-P1-18 -->
    <origin xyz="-9.9986E-05 -0.115 -0.059738" rpy="0 0 0" />
    <parent link="pelvis_link" />
    <child link="R_hip_roll_link" />
    <axis xyz="1 0 0" />
    <limit lower="-0.83" upper="0.12" effort="52" velocity="16.441001554" />
  </joint>
  <link name="R_hip_yaw_link">
    <inertial>
      <origin xyz="-0.0004713 0.0022785 -0.12678" rpy="0 0 0" />
      <mass value="3.65" />
      <inertia ixx="0.012184" ixy="-2.7E-06" ixz="0.0001216" iyy="0.014737" iyz="0.0001071" izz="0.0082214" />
    </inertial>
    <visual>
      <origin xyz="0 0 0" rpy="0 0 0" />
      <geometry>
        <mesh filename="meshes/R_hip_yaw_link.STL" />
      </geometry>
      <material name="">
        <color rgba="0.79216 0.81961 0.93333 1" />
      </material>
    </visual>
    <collision>
      <origin xyz="-2.7849E-05 -0.0008477 -0.11745" rpy="1.570796327 0 0" />
      <geometry>
        <cylinder radius="0.025" length="0.04"/>
      </geometry>
    </collision>
  </link>
  <joint name="R_hip_yaw_joint" type="revolute"><!-- EC-6408-P2-25 -->
    <origin xyz="0 0 0" rpy="0 0 0" />
    <parent link="R_hip_roll_link" />
    <child link="R_hip_yaw_link" />
    <axis xyz="0 0 1" />
    <limit lower="-0.89" upper="0.89" effort="40" velocity="15.603243513" />
  </joint>
  <link name="R_hip_pitch_link">
    <inertial>
      <origin xyz="0.011017 -0.002621 -0.13561" rpy="0 0 0" />
      <mass value="2.05" />
      <inertia ixx="0.033387" ixy="-9.2E-06" ixz="0.0010502" iyy="0.032236" iyz="0.0001658" izz="0.0091047" />
    </inertial>
    <visual>
      <origin xyz="0 0 0" rpy="0 0 0" />
      <geometry>
        <mesh filename="meshes/R_hip_pitch_link.STL" />
      </geometry>
      <material name="">
        <color rgba="0.79216 0.81961 0.93333 1" />
      </material>
    </visual>
    <collision>
      <origin xyz="0 0 -0.12" rpy="0 0 0" />
      <geometry>
        <cylinder radius="0.025" length="0.09"/>
      </geometry>
    </collision>
  </link>
  <joint name="R_hip_pitch_joint" type="revolute"><!-- EC-A10020-P2-24 -->
    <origin xyz="0 0 -0.14" rpy="0 0 0" />
    <parent link="R_hip_yaw_link" />
    <child link="R_hip_pitch_link" />
    <axis xyz="0 1 0" />
    <limit lower="-1.64" upper="0.89" effort="130" velocity="12.88052988" />
  </joint>
  <link name="R_knee_link">
    <inertial>
      <origin xyz="0.004517 0.0006816 -0.10176" rpy="0 0 0" />
      <mass value="5.85" />
      <inertia ixx="0.099954" ixy="8.42E-05" ixz="0.0016312" iyy="0.10289" iyz="-0.0007782" izz="0.010779" />
    </inertial>
    <visual>
      <origin xyz="0 0 0" rpy="0 0 0" />
      <geometry>
        <mesh filename="meshes/R_knee_link.STL" />
      </geometry>
      <material name="">
        <color rgba="0.79216 0.81961 0.93333 1" />
      </material>
    </visual>
    <collision>
      <origin xyz="0 0 -0.19" rpy="0 0 0" />
      <geometry>
        <cylinder radius="0.025" length="0.1"/>
      </geometry>
    </collision>
    <collision>
      <origin xyz="0 0 -0.35" rpy="0 0 0" />
      <geometry>
        <cylinder radius="0.025" length="0.1"/>
      </geometry>
    </collision>
    <collision>
      <origin xyz="0 0 0.0" rpy="1.570796327 0 0" />
      <geometry>
        <cylinder radius="0.025" length="0.1"/>
      </geometry>
    </collision>
  </link>
  <joint name="R_knee_joint" type="revolute"><!-- EC-A10020-P2-24 -->
    <origin xyz="0 0 -0.28496" rpy="0 0 0" />
    <parent link="R_hip_pitch_link" />
    <child link="R_knee_link" />
    <axis xyz="0 1 0" />
    <limit lower="-0.1" upper="2.35" effort="130" velocity="12.88052988" />
  </joint>
  <link name="R_ankle_pitch_link">
    <inertial>
      <origin xyz="0 -5.25E-05 0.0029854" rpy="0 0 0" />
      <mass value="0.046" />
      <inertia ixx="3.9E-06" ixy="0" ixz="0" iyy="3.6E-06" iyz="0" izz="3.4E-06" />
    </inertial>
    <visual>
      <origin xyz="0 0 0" rpy="0 0 0" />
      <geometry>
        <mesh filename="meshes/R_ankle_pitch_link.STL" />
      </geometry>
      <material name="">
        <color rgba="0.79216 0.81961 0.93333 1" />
      </material>
    </visual>
    <collision>
      <origin xyz="0 0 0" rpy="0 0 0" />
      <geometry>
        <cylinder radius="0.001" length="0.001"/>
      </geometry>
    </collision>
  </link>
  <joint name="R_ankle_pitch_joint" type="revolute"><!-- EC-A4310-P2-36 -->
    <origin xyz="0 1.39E-05 -0.45087" rpy="0 0 0" />
    <parent link="R_knee_link" />
    <child link="R_ankle_pitch_link" />
    <axis xyz="0 1 0" />
    <limit lower="-0.43" upper="0.43" effort="36" velocity="9.320058206" />
  </joint>
  <link name="R_ankle_roll_link">
    <inertial>
      <origin xyz="0.031138 2.29E-05 -0.033992" rpy="0 0 0" />
      <mass value="0.7" />
      <inertia ixx="0.0004381" ixy="-3E-07" ixz="0.0002452" iyy="0.003321" iyz="2E-07" izz="0.0034737" />
    </inertial>
    <visual>
      <origin xyz="0 0 0" rpy="0 0 0" />
      <geometry>
        <mesh filename="meshes/R_ankle_roll_link.STL" />
      </geometry>
      <material name="">
        <color rgba="0.79216 0.81961 0.93333 1" />
      </material>
    </visual>
    <collision>
      <origin xyz="-0.063 0.027 -0.047" rpy="0 0 0"/>
      <geometry>
        <sphere radius="0.005"/>
      </geometry>
    </collision>
    <collision>
      <origin xyz="-0.063 -0.027 -0.047" rpy="0 0 0"/>
      <geometry>
        <sphere radius="0.005"/>
      </geometry>
    </collision>
    <collision>
      <origin xyz="-0.071 0 -0.047" rpy="0 0 0"/>
      <geometry>
        <sphere radius="0.005"/>
      </geometry>
    </collision>

    <collision>
      <origin xyz="0.143 0.027 -0.047" rpy="0 0 0"/>
      <geometry>
        <sphere radius="0.005"/>
      </geometry>
    </collision>
    <collision>
      <origin xyz="0.143 -0.027 -0.047" rpy="0 0 0"/>
      <geometry>
        <sphere radius="0.005"/>
      </geometry>
    </collision>
    <collision>
      <origin xyz="0.156 0 -0.047" rpy="0 0 0"/>
      <geometry>
        <sphere radius="0.005"/>
      </geometry>
    </collision>
  </link>
  <joint name="R_ankle_roll_joint" type="revolute"><!-- EC-A4310-P2-36 -->
    <origin xyz="0 0 0" rpy="0 0 0" />
    <parent link="R_ankle_pitch_link" />
    <child link="R_ankle_roll_link" />
    <axis xyz="1 0 0" />
    <limit lower="-0.43" upper="0.43" effort="36" velocity="9.320058206" />
  </joint>
<!-- torso -->
  <link name="torso_link">
    <inertial>
      <origin xyz="-0.0089007 -0.0039058 0.2485" rpy="0 0 0" />
      <mass value="19.078" />
      <inertia ixx="0.35363" ixy="0.0031429" ixz="0.0051754" iyy="0.33182" iyz="-0.0025138" izz="0.16869" />
    </inertial>
    <visual>
      <origin xyz="0 0 0" rpy="0 0 0" />
      <geometry>
        <mesh filename="meshes/torso_link.STL" />
      </geometry>
      <material name="">
        <color rgba="0.79216 0.81961 0.93333 1" />
      </material>
    </visual>
    <collision>
      <origin xyz="-0.01 0 0.25" rpy="0 0 0" />
      <geometry>
        <box size="0.25 0.16 0.37"/>
      </geometry>
    </collision>
  </link>
  <joint name="pelvis_joint" type="revolute">
    <origin xyz="0 0 0" rpy="0 0 0" />
    <parent link="pelvis_link" />
    <child link="torso_link" />
    <axis xyz="0 0 1" />
    <limit lower="-1.04" upper="1.04" effort="42" velocity="8.58701992" />
  </joint>
<!-- Left arm -->
  <link name="L_shoulder_pitch_link">
    <inertial>
      <origin xyz="0.0034819 -0.0047797 -1.2E-06" rpy="0 0 0" />
      <mass value="1.35" />
      <inertia ixx="0.0016146" ixy="-1.99E-05" ixz="-1E-07" iyy="0.0012512" iyz="-2E-07" izz="0.0014304" />
    </inertial>
    <visual>
      <origin xyz="0 0 0" rpy="0 0 0" />
      <geometry>
        <mesh filename="meshes/L_shoulder_pitch_link.STL" />
      </geometry>
      <material name="">
        <color rgba="0.79216 0.81961 0.93333 1" />
      </material>
    </visual>
    <collision>
      <!-- <origin xyz="0 0 0" rpy="0 0 0" /> -->
      <origin xyz="0 0 0" rpy="1.570796327 0 1.570796327"/>
      <geometry>
        <cylinder radius="0.025" length="0.03"/>
        <!-- <mesh filename="meshes/L_shoulder_pitch_link.STL" /> -->
      </geometry>
    </collision>
  </link>
  <joint name="L_shoulder_pitch_joint" type="revolute"><!-- CRA-RI60-80 -->
    <origin xyz="-0.00015827 0.22119 0.38344" rpy="0.2618 0 0" />
    <parent link="torso_link" />
    <child link="L_shoulder_pitch_link" />
    <axis xyz="0 1 0" />
    <limit lower="-1.48" upper="1.48" effort="42" velocity="8.58701992" />
  </joint>
  <link name="L_shoulder_roll_link">
    <inertial>
      <origin xyz="0.0001178 0.0023667 -0.056312" rpy="0 0 0" />
      <mass value="0.55" />
      <inertia ixx="0.0014965" ixy="1E-07" ixz="-1.21E-05" iyy="0.0018786" iyz="8.8E-06" izz="0.0011623" />
    </inertial>
    <visual>
      <origin xyz="0 0 0" rpy="-0.2618 0 0" />
      <geometry>
        <mesh filename="meshes/L_shoulder_roll_link.STL" />
      </geometry>
      <material name="">
        <color rgba="0.79216 0.81961 0.93333 1" />
      </material>
    </visual>
    <collision>
      <origin xyz="0 -0.001 -0.09" rpy="-0.2618 0 0" />
      <geometry>
        <cylinder radius="0.02" length="0.03"/>
      </geometry>
    </collision>
  </link>
  <joint name="L_shoulder_roll_joint" type="revolute"><!-- CRA-RI60-80 -->
    <origin xyz="0 0 0" rpy="0 0 0" />
    <parent link="L_shoulder_pitch_link" />
    <child link="L_shoulder_roll_link" />
    <axis xyz="1 0 0" />
    <limit lower="-0.12" upper="3.17" effort="42" velocity="8.58701992" />
  </joint>
  <link name="L_shoulder_yaw_link">
    <inertial>
      <origin xyz="0.0030369 -0.000691 0.048579" rpy="0 0 0" />
      <mass value="1.95" />
      <inertia ixx="0.0059016" ixy="-2.9E-06" ixz="0.0002786" iyy="0.0057612" iyz="-6.3E-06" izz="0.0016272" />
    </inertial>
    <visual>
      <origin xyz="0 0 0" rpy="0 0 -1.570796327" />
      <geometry>
        <mesh filename="meshes/L_shoulder_yaw_link.STL" />
      </geometry>
      <material name="">
        <color rgba="0.79216 0.81961 0.93333 1" />
      </material>
    </visual>
    <collision>
      <origin xyz="0 0 0.05" rpy="0 0 0" />
      <geometry>
        <cylinder radius="0.02" length="0.06"/>
      </geometry>
    </collision>
  </link>
  <joint name="L_shoulder_yaw_joint" type="revolute"><!-- CRA-RI50-70 -->
    <origin xyz="0 -0.043208 -0.25042" rpy="-0.2618 0 0" />
    <parent link="L_shoulder_roll_link" />
    <child link="L_shoulder_yaw_link" />
    <axis xyz="0 0 1" />
    <limit lower="-1.69" upper="1.69" effort="23" velocity="10.157816247" />
  </joint>
  <link name="L_elbow_link">
    <inertial>
      <origin xyz="-0.0013729 0.0051926 -0.01857" rpy="0 0 0" />
      <mass value="0.25" />
      <inertia ixx="0.0003112" ixy="-1.1E-06" ixz="1.1E-06" iyy="0.0005758" iyz="2.23E-05" izz="0.0005034" />
    </inertial>
    <visual>
      <origin xyz="0 0 0" rpy="0 0 -1.570796327" />
      <geometry>
        <mesh filename="meshes/L_elbow_link.STL" />
      </geometry>
      <material name="">
        <color rgba="0.79216 0.81961 0.93333 1" />
      </material>
    </visual>
    <collision>
      <origin xyz="0 0 -0.02" rpy="0 0 -1.570796327" />
      <geometry>
        <cylinder radius="0.02" length="0.03"/>
      </geometry>
    </collision>
  </link>
  <joint name="L_elbow_joint" type="revolute"><!-- CRA-RI50-70 -->
    <origin xyz="0 0 0" rpy="0 0 0" />
    <parent link="L_shoulder_yaw_link" />
    <child link="L_elbow_link" />
    <axis xyz="0 1 0" />
    <limit lower="-1.95" upper="0.87" effort="23" velocity="10.157816247" />
  </joint>
  <link name="L_forearm_yaw_link">
    <inertial>
      <origin xyz="0.0014016 0.0001246 0.09169" rpy="0 0 0" />
      <mass value="1.05" />
      <inertia ixx="0.0016627" ixy="3.5E-06" ixz="2.96E-05" iyy="0.001822" iyz="-5.7E-06" izz="0.0007356" />
    </inertial>
    <visual>
      <origin xyz="0 0 0" rpy="0 0 0" />
      <geometry>
        <mesh filename="meshes/L_forearm_yaw_link.STL" />
      </geometry>
      <material name="">
        <color rgba="0.79216 0.81961 0.93333 1" />
      </material>
    </visual>
    <collision>
      <origin xyz="0 0 0.082" rpy="0 0 0" />
      <geometry>
        <cylinder radius="0.025" length="0.03"/>
      </geometry>
    </collision>
  </link>
  <joint name="L_forearm_yaw_joint" type="revolute"><!-- CRA-RI40-52 -->
    <origin xyz="0 0 -0.209" rpy="0 0 0" />
    <parent link="L_elbow_link" />
    <child link="L_forearm_yaw_link" />
    <axis xyz="0 0 1" />
    <limit lower="-1.53" upper="1.53" effort="8.3" velocity="12.356931104" />
  </joint>
  <link name="L_wrist_roll_link">
    <inertial>
      <origin xyz="0 -0.0047393 -2.85E-05" rpy="0 0 0" />
      <mass value="0.25" />
      <inertia ixx="8.23E-05" ixy="0" ixz="0" iyy="5.6E-05" iyz="2E-07" izz="8.3E-05" />
    </inertial>
    <visual>
      <origin xyz="0 0 0" rpy="0 0 0" />
      <geometry>
        <mesh filename="meshes/L_wrist_roll_link.STL" />
      </geometry>
      <material name="">
        <color rgba="0.79216 0.81961 0.93333 1" />
      </material>
    </visual>
    <collision>
      <origin xyz="0 0 0" rpy="0 1.570796327 0" />
      <geometry>
        <cylinder radius="0.015" length="0.01"/>
      </geometry>
    </collision>
  </link>
  <joint name="L_wrist_roll_joint" type="revolute"><!-- CRA-RI30-40 -->
    <origin xyz="0 0 0" rpy="0 0 0" />
    <parent link="L_forearm_yaw_link" />
    <child link="L_wrist_roll_link" />
    <axis xyz="1 0 0" />
    <limit lower="-2.3" upper="1.39" effort="3.3" velocity="12.356931104" />
  </joint>
  <link name="L_wrist_pitch_link">
    <inertial>
      <origin xyz="8.81E-05 0.0081922 -0.051309" rpy="0 0 0" />
      <mass value="0.16" />
      <inertia ixx="0.0001452" ixy="-2E-07" ixz="2E-07" iyy="0.0001194" iyz="-4.49E-05" izz="6.56E-05" />
    </inertial>
    <visual>
      <origin xyz="0 0 0" rpy="0 0 0" />
      <geometry>
        <mesh filename="meshes/L_wrist_pitch_link.STL" />
      </geometry>
      <material name="">
        <color rgba="0.79216 0.81961 0.93333 1" />
      </material>
    </visual>
    <collision>
      <origin xyz="0 0 -0.16" rpy="0 0 0" />
      <geometry>
        <box size="0.06 0.03 0.18"/>
      </geometry>
    </collision>
  </link>
  <joint name="L_wrist_pitch_joint" type="revolute"><!-- CRA-RI30-40 -->
    <origin xyz="0 0 0" rpy="0 0 0" />
    <parent link="L_wrist_roll_link" />
    <child link="L_wrist_pitch_link" />
    <axis xyz="0 1 0" />
    <limit lower="-1.78" upper="1.67" effort="3.3" velocity="12.356931104" />
  </joint>
<!-- Right arm -->
  <link name="R_shoulder_pitch_link">
    <inertial>
      <origin xyz="0.003482 0.0047796 -1.4E-06" rpy="0 0 0" />
      <mass value="1.35" />
      <inertia ixx="0.0016147" ixy="1.99E-05" ixz="-2E-07" iyy="0.0012512" iyz="2E-07" izz="0.0014303" />
    </inertial>
    <visual>
      <origin xyz="0 0 0" rpy="0 0 0" />
      <geometry>
        <mesh filename="meshes/R_shoulder_pitch_link.STL" />
      </geometry>
      <material name="">
        <color rgba="0.79216 0.81961 0.93333 1" />
      </material>
    </visual>
    <collision>
      <origin xyz="0 0 0" rpy="1.570796327 0 1.570796327"/>
      <geometry>
        <cylinder radius="0.025" length="0.03"/>
      </geometry>
    </collision>
  </link>
  <joint name="R_shoulder_pitch_joint" type="revolute"><!-- CRA-RI60-80 -->
    <origin xyz="-0.00015827 -0.22119 0.38344" rpy="-0.2618 0 0" />
    <parent link="torso_link" />
    <child link="R_shoulder_pitch_link" />
    <axis xyz="0 1 0" />
    <limit lower="-1.48" upper="1.48" effort="42" velocity="8.58701992" />
  </joint>
  <link name="R_shoulder_roll_link">
    <inertial>
      <origin xyz="0.00012 -0.0023541 -0.056316" rpy="0 0 0" />
      <mass value="0.55" />
      <inertia ixx="0.0014966" ixy="1E-07" ixz="-1.21E-05" iyy="0.0018788" iyz="-8.8E-06" izz="0.0011624" />
    </inertial>
    <visual>
      <origin xyz="0 0 0" rpy="0.2618 0 0" />
      <geometry>
        <mesh filename="meshes/R_shoulder_roll_link.STL" />
      </geometry>
      <material name="">
        <color rgba="0.79216 0.81961 0.93333 1" />
      </material>
    </visual>
    <collision>
      <origin xyz="0 -0.001 -0.09" rpy="0.2618 0 0" />
      <geometry>
        <cylinder radius="0.02" length="0.03"/>
      </geometry>
    </collision>
  </link>
  <joint name="R_shoulder_roll_joint" type="revolute"><!-- CRA-RI60-80 -->
    <origin xyz="0 0 0" rpy="0 0 0" />
    <parent link="R_shoulder_pitch_link" />
    <child link="R_shoulder_roll_link" />
    <axis xyz="1 0 0" />
    <limit lower="-3.17" upper="0.12" effort="42" velocity="8.58701992" />
  </joint>
  <link name="R_shoulder_yaw_link">
    <inertial>
      <origin xyz="0.0030364 0.0006912 0.048579" rpy="0 0 0" />
      <mass value="1.95" />
      <inertia ixx="0.0059016" ixy="3E-06" ixz="0.0002787" iyy="0.0057611" iyz="6.3E-06" izz="0.001627" />
    </inertial>
    <visual>
      <origin xyz="0 0 0" rpy="0 0 1.570796327" />
      <geometry>
        <mesh filename="meshes/R_shoulder_yaw_link.STL" />
      </geometry>
      <material name="">
        <color rgba="0.79216 0.81961 0.93333 1" />
      </material>
    </visual>
    <collision>
      <origin xyz="0 0 0.05" rpy="0 0 -1.570796327" />
      <geometry>
        <cylinder radius="0.02" length="0.06"/>
      </geometry>
    </collision>
  </link>
  <joint name="R_shoulder_yaw_joint" type="revolute"><!-- CRA-RI50-70 -->
    <origin xyz="0 0.043208 -0.25042" rpy="0.2618 0 0" />
    <parent link="R_shoulder_roll_link" />
    <child link="R_shoulder_yaw_link" />
    <axis xyz="0 0 1" />
    <limit lower="-1.69" upper="1.69" effort="23" velocity="10.157816247" />
  </joint>
  <link name="R_elbow_link">
    <inertial>
      <origin xyz="-0.0013805 -0.0051935 -0.018572" rpy="0 0 0" />
      <mass value="0.25" />
      <inertia ixx="0.0003112" ixy="1.1E-06" ixz="1.1E-06" iyy="0.0005757" iyz="-2.23E-05" izz="0.0005034" />
    </inertial>
    <visual>
      <origin xyz="0 0 0" rpy="0 0 1.570796327" />
      <geometry>
        <mesh filename="meshes/R_elbow_link.STL" />
      </geometry>
      <material name="">
        <color rgba="0.79216 0.81961 0.93333 1" />
      </material>
    </visual>
    <collision>
      <origin xyz="0 0 -0.02" rpy="0 0 1.570796327" />
      <geometry>
        <cylinder radius="0.02" length="0.03"/>
      </geometry>
    </collision>
  </link>
  <joint name="R_elbow_joint" type="revolute"><!-- CRA-RI50-70 -->
    <origin xyz="0 0 0" rpy="0 0 0" />
    <parent link="R_shoulder_yaw_link" />
    <child link="R_elbow_link" />
    <axis xyz="0 1 0" />
    <limit lower="-0.87" upper="1.95" effort="23" velocity="10.157816247" />
  </joint>
  <link name="R_forearm_yaw_link">
    <inertial>
      <origin xyz="0.0014 -0.0001237 0.09169" rpy="0 0 0" />
      <mass value="1.05" />
      <inertia ixx="0.0016625" ixy="-3.5E-06" ixz="2.96E-05" iyy="0.0018219" iyz="5.7E-06" izz="0.0007357" />
    </inertial>
    <visual>
      <origin xyz="0 0 0" rpy="0 0 0" />
      <geometry>
        <mesh filename="meshes/R_forearm_yaw_link.STL" />
      </geometry>
      <material name="">
        <color rgba="0.79216 0.81961 0.93333 1" />
      </material>
    </visual>
    <collision>
      <origin xyz="0 0 0.082" rpy="0 0 0" />
      <geometry>
        <cylinder radius="0.025" length="0.03"/>
      </geometry>
    </collision>
  </link>
  <joint name="R_forearm_yaw_joint" type="revolute"><!-- CRA-RI40-52 -->
    <origin xyz="0 0 -0.209" rpy="0 0 0" />
    <parent link="R_elbow_link" />
    <child link="R_forearm_yaw_link" />
    <axis xyz="0 0 1" />
    <limit lower="-1.53" upper="1.53" effort="8.3" velocity="12.356931104" />
  </joint>
  <link name="R_wrist_roll_link">
    <inertial>
      <origin xyz="0 0.0047393 -2.85E-05" rpy="0 0 0" />
      <mass value="0.25" />
      <inertia ixx="8.23E-05" ixy="0" ixz="0" iyy="5.6E-05" iyz="-2E-07" izz="8.3E-05" />
    </inertial>
    <visual>
      <origin xyz="0 0 0" rpy="0 0 0" />
      <geometry>
        <mesh filename="meshes/R_wrist_roll_link.STL" />
      </geometry>
      <material name="">
        <color rgba="0.79216 0.81961 0.93333 1" />
      </material>
    </visual>
    <collision>
      <origin xyz="0 0 0" rpy="0 1.570796327 0" />
      <geometry>
        <cylinder radius="0.015" length="0.01"/>
      </geometry>
    </collision>
  </link>
  <joint name="R_wrist_roll_joint" type="revolute"><!-- CRA-RI30-40 -->
    <origin xyz="0 0 0" rpy="0 0 0" />
    <parent link="R_forearm_yaw_link" />
    <child link="R_wrist_roll_link" />
    <axis xyz="1 0 0" />
    <limit lower="-1.39" upper="2.3" effort="3.3" velocity="12.356931104" />
  </joint>
  <link name="R_wrist_pitch_link">
    <inertial>
      <origin xyz="8.81E-05 -0.0081922 -0.051309" rpy="0 0 0" />
      <mass value="0.16" />
      <inertia ixx="0.0001452" ixy="2E-07" ixz="2E-07" iyy="0.0001194" iyz="4.49E-05" izz="6.56E-05" />
    </inertial>
    <visual>
      <origin xyz="0 0 0" rpy="0 0 0" />
      <geometry>
        <mesh filename="meshes/R_wrist_pitch_link.STL" />
      </geometry>
      <material name="">
        <color rgba="0.79216 0.81961 0.93333 1" />
      </material>
    </visual>
    <collision>
      <origin xyz="0 0 -0.16" rpy="0 0 0" />
      <geometry>
        <box size="0.06 0.03 0.18"/>
      </geometry>
    </collision>
  </link>
  <joint name="R_wrist_pitch_joint" type="revolute"><!-- CRA-RI30-40 -->
    <origin xyz="0 0 0" rpy="0 0 0" />
    <parent link="R_wrist_roll_link" />
    <child link="R_wrist_pitch_link" />
    <axis xyz="0 1 0" />
    <limit lower="-1.78" upper="1.67" effort="3.3" velocity="12.356931104" />
  </joint>
<!-- Head -->
  <link name="head_yaw_link">
    <inertial>
      <origin xyz="9.42E-05 -0.0015802 -0.0048308" rpy="0 0 0" />
      <mass value="0.8" />
      <inertia ixx="0.0023797" ixy="-5E-07" ixz="7E-07" iyy="0.0005019" iyz="5.7E-06" izz="0.0023519" />
    </inertial>
    <visual>
      <origin xyz="0 0 0" rpy="0 0 0" />
      <geometry>
        <mesh filename="meshes/head_yaw_link.STL" />
      </geometry>
      <material name="">
        <color rgba="0.79216 0.81961 0.93333 1" />
      </material>
    </visual>
    <collision>
      <origin xyz="0 0 0" rpy="0 0 0" />
      <geometry>
        <box size="0.01 0.01 0.01"/>
      </geometry>
    </collision>
  </link>
  <joint name="head_yaw_joint" type="revolute">
    <origin xyz="0.011342 0 0.62019" rpy="0 0 0" />
    <parent link="torso_link" />
    <child link="head_yaw_link" />
    <axis xyz="0 0 1" />
    <limit lower="-1.57" upper="1.57" effort="2.52" velocity="29.216811679" />
  </joint>
  <link name="head_pitch_link">
    <inertial>
      <origin xyz="0.021366 0.0020556 0.027951" rpy="0 0 0" />
      <mass value="0.72904" />
      <inertia ixx="0.0033823" ixy="4.5E-05" ixz="0.0004603" iyy="0.0044162" iyz="3.21E-05" izz="0.0042325" />
    </inertial>
    <visual>
      <origin xyz="0 0 0" rpy="0 0 0" />
      <geometry>
        <mesh filename="meshes/head_pitch_link.STL" />
      </geometry>
      <material name="">
        <color rgba="0.79216 0.81961 0.93333 1" />
      </material>
    </visual>
    <collision>
      <origin xyz="0 0 0" rpy="0 0 0" />
      <geometry>
        <box size="0.01 0.12 0.12"/>
      </geometry>
    </collision>
  </link>
  <joint name="head_pitch_joint" type="revolute">
    <origin xyz="0 0 0" rpy="0 0 0" />
    <parent link="head_yaw_link" />
    <child link="head_pitch_link" />
    <axis xyz="0 1 0" />
    <limit lower="-0.38" upper="0.33" effort="1.26" velocity="58.433623357" />
  </joint>
</robot>